Workbook

Sheet piviot table of orders
A1: order_id | B1: (All)
A3: Row Labels | B3: Sum of Sales
A4: Ahmed | B4: 1175
A5: Anthony | B5: 555
A6: Bruce | B6: 1235
A7: Jay | B7: 785
A8: John | B8: 480
A9: Lisa | B9: 925
A10: MiKe | B10: 1990
A11: Ravi | B11: 835
A12: Tim | B12: 940
A13: Grand Total | B13: 8920

Sheet orders
A1: order_id | B1: date | C1: customer_id | D1: product_id | E1: qty | F1: customer_name | G1: product name | H1: price | I1: total price | J1: Calories
A2: 1125 | B2: 44958 | C2: 11 | D2: 704 | E2: 6 | F2: =VLOOKUP(C2,'customers'!A:B,2,FALSE) -> Anthony | G2: =INDEX(products!B:B, MATCH(D2, products!A:A, 0)) -> Eggs | H2: =VLOOKUP(orders[[#This Row],[product_id]],products[#All],7,0) -> 65 | I2: =orders[qty]*orders[price] -> 390 | J2: =INDEX(products!C:C,MATCH(D2,products!A:A),0) -> 155
A3: 1127 | B3: 44958 | C3: 19 | D3: 392 | E3: 2 | F3: =VLOOKUP(C3,'customers'!A:B,2,FALSE) -> Ahmed | G3: =INDEX(products!B:B, MATCH(D3, products!A:A, 0)) -> Yogurt | H3: =VLOOKUP(orders[[#This Row],[product_id]],products[#All],7,0) -> 30 | I3: =orders[qty]*orders[price] -> 60 | J3: =INDEX(products!C:C,MATCH(D3,products!A:A),0) -> 131
A4: 1152 | B4: 44958 | C4: 14 | D4: 646 | E4: 7 | F4: =VLOOKUP(C4,'customers'!A:B,2,FALSE) -> Ravi | G4: =INDEX(products!B:B, MATCH(D4, products!A:A, 0)) -> Apple | H4: =VLOOKUP(orders[[#This Row],[product_id]],products[#All],7,0) -> 200 | I4: =orders[qty]*orders[price] -> 1400 | J4: =INDEX(products!C:C,MATCH(D4,products!A:A),0) -> 41
A5: 1153 | B5: 44958 | C5: 35 | D5: 294 | E5: 9 | F5: =VLOOKUP(C5,'customers'!A:B,2,FALSE) -> MiKe | G5: =INDEX(products!B:B, MATCH(D5, products!A:A, 0)) -> Rice | H5: =VLOOKUP(orders[[#This Row],[product_id]],products[#All],7,0) -> 80 | I5: =orders[qty]*orders[price] -> 720 | J5: =INDEX(products!C:C,MATCH(D5,products!A:A),0) -> 130
A6: 1161 | B6: 44958 | C6: 35 | D6: 651 | E6: 6 | F6: =VLOOKUP(C6,'customers'!A:B,2,FALSE) -> MiKe | G6: =INDEX(products!B:B, MATCH(D6, products!A:A, 0)) -> Banana | H6: =VLOOKUP(orders[[#This Row],[product_id]],products[#All],7,0) -> 80 | I6: =orders[qty]*orders[price] -> 480 | J6: =INDEX(products!C:C,MATCH(D6,products!A:A),0) -> 41
A7: 1163 | B7: 44959 | C7: 50 | D7: 646 | E7: 4 | F7: =VLOOKUP(C7,'customers'!A:B,2,FALSE) -> Bruce | G7: =INDEX(products!B:B, MATCH(D7, products!A:A, 0)) -> Apple | H7: =VLOOKUP(orders[[#This Row],[product_id]],products[#All],7,0) -> 200 | I7: =orders[qty]*orders[price] -> 800 | J7: =INDEX(products!C:C,MATCH(D7,products!A:A),0) -> 41 | L7: sum price | M7: =SUM(orders[price]) -> 8920
A8: 1167 | B8: 44959 | C8: 35 | D8: 739 | E8: 9 | F8: =VLOOKUP(C8,'customers'!A:B,2,FALSE) -> MiKe | G8: =INDEX(products!B:B, MATCH(D8, products!A:A, 0)) -> Donut | H8: =VLOOKUP(orders[[#This Row],[product_id]],products[#All],7,0) -> 40 | I8: =orders[qty]*orders[price] -> 360 | J8: =INDEX(products!C:C,MATCH(D8,products!A:A),0) -> 152 | L8: Avg price | M8: =AVERAGE(orders[price]) -> 84.952381
A9: 1167 | B9: 44959 | C9: 35 | D9: 739 | E9: 8 | F9: =VLOOKUP(C9,'customers'!A:B,2,FALSE) -> MiKe | G9: =INDEX(products!B:B, MATCH(D9, products!A:A, 0)) -> Donut | H9: =VLOOKUP(orders[[#This Row],[product_id]],products[#All],7,0) -> 40 | I9: =orders[qty]*orders[price] -> 320 | J9: =INDEX(products!C:C,MATCH(D9,products!A:A),0) -> 152 | L9: count | M9: =COUNT(orders[price]) -> 105
A10: 1176 | B10: 44959 | C10: 11 | D10: 628 | E10: 5 | F10: =VLOOKUP(C10,'customers'!A:B,2,FALSE) -> Anthony | G10: =INDEX(products!B:B, MATCH(D10, products!A:A, 0)) -> Fish | H10: =VLOOKUP(orders[[#This Row],[product_id]],products[#All],7,0) -> 120 | I10: =orders[qty]*orders[price] -> 600 | J10: =INDEX(products!C:C,MATCH(D10,products!A:A),0) -> 41 | L10: count eggs | M10: =COUNTIF(orders[product name],"eggs") -> 10
A11: 1183 | B11: 44959 | C11: 21 | D11: 163 | E11: 7 | F11: =VLOOKUP(C11,'customers'!A:B,2,FALSE) -> Lisa | G11: =INDEX(products!B:B, MATCH(D11, products!A:A, 0)) -> Grape Juice | H11: =VLOOKUP(orders[[#This Row],[product_id]],products[#All],7,0) -> 40 | I11: =orders[qty]*orders[price] -> 280 | J11: =INDEX(products!C:C,MATCH(D11,products!A:A),0) -> #N/A | L11: sum eggs | M11: =SUMIF(orders[product name],"eggs",orders[total price]) -> 2665
A12: 1187 | B12: 44959 | C12: 19 | D12: 594 | E12: 6 | F12: =VLOOKUP(C12,'customers'!A:B,2,FALSE) -> Ahmed | G12: =INDEX(products!B:B, MATCH(D12, products!A:A, 0)) -> Chicken | H12: =VLOOKUP(orders[[#This Row],[product_id]],products[#All],7,0) -> 250 | I12: =orders[qty]*orders[price] -> 1500 | J12: =INDEX(products!C:C,MATCH(D12,products!A:A),0) -> 41
A13: 1193 | B13: 44960 | C13: 34 | D13: 651 | E13: 2 | F13: =VLOOKUP(C13,'customers'!A:B,2,FALSE) -> Jay | G13: =INDEX(products!B:B, MATCH(D13, products!A:A, 0)) -> Banana | H13: =VLOOKUP(orders[[#This Row],[product_id]],products[#All],7,0) -> 80 | I13: =orders[qty]*orders[price] -> 160 | J13: =INDEX(products!C:C,MATCH(D13,products!A:A),0) -> 41
A14: 1194 | B14: 44960 | C14: 11 | D14: 600 | E14: 9 | F14: =VLOOKUP(C14,'customers'!A:B,2,FALSE) -> Anthony | G14: =INDEX(products!B:B, MATCH(D14, products!A:A, 0)) -> Grapefruit | H14: =VLOOKUP(orders[[#This Row],[product_id]],products[#All],7,0) -> 20 | I14: =orders[qty]*orders[price] -> 180 | J14: =INDEX(products!C:C,MATCH(D14,products!A:A),0) -> 41
A15: 1195 | B15: 44960 | C15: 29 | D15: 739 | E15: 3 | F15: =VLOOKUP(C15,'customers'!A:B,2,FALSE) -> John | G15: =INDEX(products!B:B, MATCH(D15, products!A:A, 0)) -> Donut | H15: =VLOOKUP(orders[[#This Row],[product_id]],products[#All],7,0) -> 40 | I15: =orders[qty]*orders[price] -> 120 | J15: =INDEX(products!C:C,MATCH(D15,products!A:A),0) -> 152
A16: 1199 | B16: 44960 | C16: 35 | D16: 797 | F16: =VLOOKUP(C16,'customers'!A:B,2,FALSE) -> MiKe | G16: =INDEX(products!B:B, MATCH(D16, products!A:A, 0)) -> Cheese | H16: =VLOOKUP(orders[[#This Row],[product_id]],products[#All],7,0) -> 80 | I16: =orders[qty]*orders[price] -> 0 | J16: =INDEX(products!C:C,MATCH(D16,products!A:A),0) -> 250
A17: 1200 | B17: 44960 | C17: 79 | D17: 521 | E17: 3 | F17: =VLOOKUP(C17,'customers'!A:B,2,FALSE) -> Tim | G17: =INDEX(products!B:B, MATCH(D17, products!A:A, 0)) -> Carrot | H17: =VLOOKUP(orders[[#This Row],[product_id]],products[#All],7,0) -> 40 | I17: =orders[qty]*orders[price] -> 120 | J17: =INDEX(products!C:C,MATCH(D17,products!A:A),0) -> 41
A18: 1206 | B18: 44961 | C18: 11 | D18: 886 | F18: =VLOOKUP(C18,'customers'!A:B,2,FALSE) -> Anthony | G18: =INDEX(products!B:B, MATCH(D18, products!A:A, 0)) -> Avocado | H18: =VLOOKUP(orders[[#This Row],[product_id]],products[#All],7,0) -> 100 | I18: =orders[qty]*orders[price] -> 0 | J18: =INDEX(products!C:C,MATCH(D18,products!A:A),0) -> 250
A19: 1211 | B19: 44961 | C19: 79 | D19: 646 | E19: 7 | F19: =VLOOKUP(C19,'customers'!A:B,2,FALSE) -> Tim | G19: =INDEX(products!B:B, MATCH(D19, products!A:A, 0)) -> Apple | H19: =VLOOKUP(orders[[#This Row],[product_id]],products[#All],7,0) -> 200 | I19: =orders[qty]*orders[price] -> 1400 | J19: =INDEX(products!C:C,MATCH(D19,products!A:A),0) -> 41
A20: 1213 | B20: 44961 | C20: 29 | D20: 328 | E20: 10 | F20: =VLOOKUP(C20,'customers'!A:B,2,FALSE) -> John | G20: =INDEX(products!B:B, MATCH(D20, products!A:A, 0)) -> Pasta | H20: =VLOOKUP(orders[[#This Row],[product_id]],products[#All],7,0) -> 60 | I20: =orders[qty]*orders[price] -> 600 | J20: =INDEX(products!C:C,MATCH(D20,products!A:A),0) -> 131
A21: 1215 | B21: 44961 | C21: 21 | D21: 811 | E21: 3 | F21: =VLOOKUP(C21,'customers'!A:B,2,FALSE) -> Lisa | G21: =INDEX(products!B:B, MATCH(D21, products!A:A, 0)) -> Celery | H21: =VLOOKUP(orders[[#This Row],[product_id]],products[#All],7,0) -> 50 | I21: =orders[qty]*orders[price] -> 150 | J21: =INDEX(products!C:C,MATCH(D21,products!A:A),0) -> 250
A22: 1227 | B22: 44961 | C22: 50 | D22: 704 | E22: 5 | F22: =VLOOKUP(C22,'customers'!A:B,2,FALSE) -> Bruce | G22: =INDEX(products!B:B, MATCH(D22, products!A:A, 0)) -> Eggs | H22: =VLOOKUP(orders[[#This Row],[product_id]],products[#All],7,0) -> 65 | I22: =orders[qty]*orders[price] -> 325 | J22: =INDEX(products!C:C,MATCH(D22,products!A:A),0) -> 155
A23: 1233 | B23: 44962 | C23: 79 | D23: 328 | E23: 10 | F23: =VLOOKUP(C23,'customers'!A:B,2,FALSE) -> Tim | G23: =INDEX(products!B:B, MATCH(D23, products!A:A, 0)) -> Pasta | H23: =VLOOKUP(orders[[#This Row],[product_id]],products[#All],7,0) -> 60 | I23: =orders[qty]*orders[price] -> 600 | J23: =INDEX(products!C:C,MATCH(D23,products!A:A),0) -> 131
A24: 1235 | B24: 44962 | C24: 14 | D24: 163 | E24: 10 | F24: =VLOOKUP(C24,'customers'!A:B,2,FALSE) -> Ravi | G24: =INDEX(products!B:B, MATCH(D24, products!A:A, 0)) -> Grape Juice | H24: =VLOOKUP(orders[[#This Row],[product_id]],products[#All],7,0) -> 40 | I24: =orders[qty]*orders[price] -> 400 | J24: =INDEX(products!C:C,MATCH(D24,products!A:A),0) -> #N/A
A25: 1255 | B25: 44962 | C25: 50 | D25: 521 | E25: 2 | F25: =VLOOKUP(C25,'customers'!A:B,2,FALSE) -> Bruce | G25: =INDEX(products!B:B, MATCH(D25, products!A:A, 0)) -> Carrot | H25: =VLOOKUP(orders[[#This Row],[product_id]],products[#All],7,0) -> 40 | I25: =orders[qty]*orders[price] -> 80 | J25: =INDEX(products!C:C,MATCH(D25,products!A:A),0) -> 41
A26: 1257 | B26: 44962 | C26: 11 | D26: 590 | E26: 8 | F26: =VLOOKUP(C26,'customers'!A:B,2,FALSE) -> Anthony | G26: =INDEX(products!B:B, MATCH(D26, products!A:A, 0)) -> French Fries | H26: =VLOOKUP(orders[[#This Row],[product_id]],products[#All],7,0) -> 50 | I26: =orders[qty]*orders[price] -> 400 | J26: =INDEX(products!C:C,MATCH(D26,products!A:A),0) -> 41
A27: 1258 | B27: 44962 | C27: 34 | D27: 704 | E27: 4 | F27: =VLOOKUP(C27,'customers'!A:B,2,FALSE) -> Jay | G27: =INDEX(products!B:B, MATCH(D27, products!A:A, 0)) -> Eggs | H27: =VLOOKUP(orders[[#This Row],[product_id]],products[#All],7,0) -> 65 | I27: =orders[qty]*orders[price] -> 260 | J27: =INDEX(products!C:C,MATCH(D27,products!A:A),0) -> 155
A28: 1273 | B28: 44963 | C28: 50 | D28: 886 | E28: 3 | F28: =VLOOKUP(C28,'customers'!A:B,2,FALSE) -> Bruce | G28: =INDEX(products!B:B, MATCH(D28, products!A:A, 0)) -> Avocado | H28: =VLOOKUP(orders[[#This Row],[product_id]],products[#All],7,0) -> 100 | I28: =orders[qty]*orders[price] -> 300 | J28: =INDEX(products!C:C,MATCH(D28,products!A:A),0) -> 250
A29: 1277 | B29: 44963 | C29: 34 | D29: 704 | E29: 6 | F29: =VLOOKUP(C29,'customers'!A:B,2,FALSE) -> Jay | G29: =INDEX(products!B:B, MATCH(D29, products!A:A, 0)) -> Eggs | H29: =VLOOKUP(orders[[#This Row],[product_id]],products[#All],7,0) -> 65 | I29: =orders[qty]*orders[price] -> 390 | J29: =INDEX(products!C:C,MATCH(D29,products!A:A),0) -> 155
A30: 1289 | B30: 44963 | C30: 19 | D30: 811 | E30: 6 | F30: =VLOOKUP(C30,'customers'!A:B,2,FALSE) -> Ahmed | G30: =INDEX(products!B:B, MATCH(D30, products!A:A, 0)) -> Celery | H30: =VLOOKUP(orders[[#This Row],[product_id]],products[#All],7,0) -> 50 | I30: =orders[qty]*orders[price] -> 300 | J30: =INDEX(products!C:C,MATCH(D30,products!A:A),0) -> 250
... A38: 1302 | B38: 44964 | C38: 34 | D38: 328 | E38: 3 | F38: =VLOOKUP(C38,'customers'!A:B,2,FALSE) -> Jay | G38: =INDEX(products!B:B, MATCH(D38, products!A:A, 0)) -> Pasta | H38: =VLOOKUP(orders[[#This Row],[product_id]],products[#All],7,0) -> 60 | I38: =orders[qty]*orders[price] -> 180 | J38: =INDEX(products!C:C,MATCH(D38,products!A:A),0) -> 131
A39: 1309 | B39: 44965 | C39: 34 | D39: 163 | F39: =VLOOKUP(C39,'customers'!A:B,2,FALSE) -> Jay | G39: =INDEX(products!B:B, MATCH(D39, products!A:A, 0)) -> Grape Juice | H39: =VLOOKUP(orders[[#This Row],[product_id]],products[#All],7,0) -> 40 | I39: =orders[qty]*orders[price] -> 0 | J39: =INDEX(products!C:C,MATCH(D39,products!A:A),0) -> #N/A
A40: 1310 | B40: 44965 | C40: 79 | D40: 484 | E40: 3 | F40: =VLOOKUP(C40,'customers'!A:B,2,FALSE) -> Tim | G40: =INDEX(products!B:B, MATCH(D40, products!A:A, 0)) -> Hamburger | H40: =VLOOKUP(orders[[#This Row],[product_id]],products[#All],7,0) -> 70 | I40: =orders[qty]*orders[price] -> 210 | J40: =INDEX(products!C:C,MATCH(D40,products!A:A),0) -> 131
A41: 1318 | B41: 44965 | C41: 29 | D41: 794 | E41: 3 | F41: =VLOOKUP(C41,'customers'!A:B,2,FALSE) -> John | G41: =INDEX(products!B:B, MATCH(D41, products!A:A, 0)) -> Grilled Cheese | H41: =VLOOKUP(orders[[#This Row],[product_id]],products[#All],7,0) -> 100 | I41: =orders[qty]*orders[price] -> 300 | J41: =INDEX(products!C:C,MATCH(D41,products!A:A),0) -> 440
A42: 1319 | B42: 44965 | C42: 14 | D42: 521 | E42: 6 | F42: =VLOOKUP(C42,'customers'!A:B,2,FALSE) -> Ravi | G42: =INDEX(products!B:B, MATCH(D42, products!A:A, 0)) -> Carrot | H42: =VLOOKUP(orders[[#This Row],[product_id]],products[#All],7,0) -> 40 | I42: =orders[qty]*orders[price] -> 240 | J42: =INDEX(products!C:C,MATCH(D42,products!A:A),0) -> 41
A43: 1321 | B43: 44965 | C43: 21 | D43: 594 | E43: 7 | F43: =VLOOKUP(C43,'customers'!A:B,2,FALSE) -> Lisa | G43: =INDEX(products!B:B, MATCH(D43, products!A:A, 0)) -> Chicken | H43: =VLOOKUP(orders[[#This Row],[product_id]],products[#All],7,0) -> 250 | I43: =orders[qty]*orders[price] -> 1750 | J43: =INDEX(products!C:C,MATCH(D43,products!A:A),0) -> 41
A44: 1323 | B44: 44966 | C44: 79 | D44: 646 | E44: 9 | F44: =VLOOKUP(C44,'customers'!A:B,2,FALSE) -> Tim | G44: =INDEX(products!B:B, MATCH(D44, products!A:A, 0)) -> Apple | H44: =VLOOKUP(orders[[#This Row],[product_id]],products[#All],7,0) -> 200 | I44: =orders[qty]*orders[price] -> 1800 | J44: =INDEX(products!C:C,MATCH(D44,products!A:A),0) -> 41
A45: 1324 | B45: 44966 | C45: 19 | D45: 594 | E45: 8 | F45: =VLOOKUP(C45,'customers'!A:B,2,FALSE) -> Ahmed | G45: =INDEX(products!B:B, MATCH(D45, products!A:A, 0)) -> Chicken | H45: =VLOOKUP(orders[[#This Row],[product_id]],products[#All],7,0) -> 250 | I45: =orders[qty]*orders[price] -> 2000 | J45: =INDEX(products!C:C,MATCH(D45,products!A:A),0) -> 41
A46: 1327 | B46: 44966 | C46: 50 | D46: 392 | E46: 9 | F46: =VLOOKUP(C46,'customers'!A:B,2,FALSE) -> Bruce | G46: =INDEX(products!B:B, MATCH(D46, products!A:A, 0)) -> Yogurt | H46: =VLOOKUP(orders[[#This Row],[product_id]],products[#All],7,0) -> 30 | I46: =orders[qty]*orders[price] -> 270 | J46: =INDEX(products!C:C,MATCH(D46,products!A:A),0) -> 131
A47: 1330 | B47: 44966 | C47: 29 | D47: 804 | E47: 10 | F47: =VLOOKUP(C47,'customers'!A:B,2,FALSE) -> John | G47: =INDEX(products!B:B, MATCH(D47, products!A:A, 0)) -> Broccoli | H47: =VLOOKUP(orders[[#This Row],[product_id]],products[#All],7,0) -> 30 | I47: =orders[qty]*orders[price] -> 300 | J47: =INDEX(products!C:C,MATCH(D47,products!A:A),0) -> 250
...

Sheet products
A1: product_id | B1: product_name | C1: calories | D1: protein | E1: carbs | F1: fat | G1: price (in INR)
A2: 646 | B2: Apple | C2: 52 | D2: 0.26 | E2: 13.8 | F2: 0.17 | G2: 200
A3: 651 | B3: Banana | C3: 89 | D3: 1.09 | E3: 22.8 | F3: 0.33 | G3: 80
A4: 886 | B4: Avocado | C4: 322 | D4: 4.02 | E4: 17.15 | F4: 29.47 | G4: 100
A5: 804 | B5: Broccoli | C5: 34 | D5: 2.82 | E5: 6.64 | F5: 0.37 | G5: 30
A6: 594 | B6: Chicken | C6: 335 | D6: 31.02 | E6: 0 | F6: 23.11 | G6: 250
A7: 628 | B7: Fish | C7: 206 | D7: 20.26 | E7: 0 | F7: 13.92 | G7: 120
A8: 294 | B8: Rice | C8: 130 | D8: 2.69 | E8: 28.73 | F8: 0.28 | G8: 80
A9: 328 | B9: Pasta | C9: 131 | D9: 5.47 | E9: 25.77 | F9: 1.03 | G9: 60
A10: 521 | B10: Carrot | C10: 41 | D10: 0.93 | E10: 9.58 | F10: 0.24 | G10: 40
A11: 811 | B11: Celery | C11: 16 | D11: 0.69 | E11: 3.06 | F11: 0.17 | G11: 50
A12: 797 | B12: Cheese | C12: 402 | D12: 25.09 | E12: 3.09 | F12: 33.82 | G12: 80
A13: 862 | B13: Chocolate Cake | C13: 452 | D13: 3.75 | E13: 44.61 | F13: 29.11 | G13: 200
... A21: 484 | B21: Hamburger | C21: 250 | D21: 13.29 | E21: 17.32 | F21: 14.62 | G21: 70

Sheet customers
A1: customer_id | B1: customer_name
A2: 34 | B2: Jay
A3: 29 | B3: John
A4: 79 | B4: Tim
A5: 14 | B5: Ravi
A6: 21 | B6: Lisa
A7: 19 | B7: Ahmed
A8: 35 | B8: MiKe
A9: 50 | B9: Bruce
A10: 35 | B10: Mahesh
A11: 11 | B11: Anthony
